20210312 15:59:28 [83] ERROR Web [(null)] - StackTrace
   at System.Data.Entity.Internal.InternalContext.SaveChanges()
   at Suftnet.Cos.DataAccess.DeliveryOrder.Insert(DeliveryOrderDto entity) in E:\Git\Web\Irit\Irit\Suftnet.Cos.DataAccess\LinqtoSql\Implementation\DeliveryOrder.cs:line 52
   at Suftnet.Cos.Mobile.DeliveryOrderController.<>c__DisplayClass8_0.<Create>b__0() in E:\Git\Web\Irit\Irit\Suftnet.Cos\Controllers\Api\v1\DeliveryOrderController.cs:line 93
   at System.Threading.Tasks.Task`1.InnerInvoke()
   at System.Threading.Tasks.Task.Execute()
--- End of stack trace from previous location where exception was thrown ---
   at System.Runtime.ExceptionServices.ExceptionDispatchInfo.Throw()
   at System.Runtime.CompilerServices.TaskAwaiter.HandleNonSuccessAndDebuggerNotification(Task task)
   at System.Runtime.CompilerServices.TaskAwaiter`1.GetResult()
   at Suftnet.Cos.Mobile.DeliveryOrderController.<Create>d__8.MoveNext() in E:\Git\Web\Irit\Irit\Suftnet.Cos\Controllers\Api\v1\DeliveryOrderController.cs:line 93
--- End of stack trace from previous location where exception was thrown ---
   at System.Runtime.ExceptionServices.ExceptionDispatchInfo.Throw()
   at System.Runtime.CompilerServices.TaskAwaiter.HandleNonSuccessAndDebuggerNotification(Task task)
   at System.Threading.Tasks.TaskHelpersExtensions.<CastToObject>d__3`1.MoveNext()
--- End of stack trace from previous location where exception was thrown ---
   at System.Runtime.ExceptionServices.ExceptionDispatchInfo.Throw()
   at System.Runtime.CompilerServices.TaskAwaiter.HandleNonSuccessAndDebuggerNotification(Task task)
   at System.Web.Http.Controllers.ApiControllerActionInvoker.<InvokeActionAsyncCore>d__0.MoveNext()
--- End of stack trace from previous location where exception was thrown ---
   at System.Runtime.ExceptionServices.ExceptionDispatchInfo.Throw()
   at System.Runtime.CompilerServices.TaskAwaiter.HandleNonSuccessAndDebuggerNotification(Task task)
   at System.Web.Http.Controllers.ActionFilterResult.<ExecuteAsync>d__2.MoveNext()
--- End of stack trace from previous location where exception was thrown ---
   at System.Runtime.ExceptionServices.ExceptionDispatchInfo.Throw()
   at System.Runtime.CompilerServices.TaskAwaiter.HandleNonSuccessAndDebuggerNotification(Task task)
   at System.Web.Http.Controllers.ExceptionFilterResult.<ExecuteAsync>d__0.MoveNext()Messages
An error occurred while updating the entries. See the inner exception for details.
--------------------------------------------
Request.Body = {"orderId":"fdce2caf-2c11-4b4a-9895-6916e79f2ce4","userId":"fee9a2ef-c152-45b6-a2ee-5c74fe1cabf9"}
--------------------------------------------
Inner Exception
Messages
An error occurred while updating the entries. See the inner exception for details.Messages
The conversion of a datetime2 data type to a smalldatetime data type resulted in an out-of-range value.
The statement has been terminated.
--------------------------------------------------------------------------------------------
20210312 16:00:10 [83] ERROR Web [(null)] - StackTrace
   at System.Data.Entity.Internal.InternalContext.SaveChanges()
   at Suftnet.Cos.DataAccess.DeliveryOrder.Insert(DeliveryOrderDto entity) in E:\Git\Web\Irit\Irit\Suftnet.Cos.DataAccess\LinqtoSql\Implementation\DeliveryOrder.cs:line 52
   at Suftnet.Cos.Mobile.DeliveryOrderController.<>c__DisplayClass8_0.<Create>b__0() in E:\Git\Web\Irit\Irit\Suftnet.Cos\Controllers\Api\v1\DeliveryOrderController.cs:line 93
   at System.Threading.Tasks.Task`1.InnerInvoke()
   at System.Threading.Tasks.Task.Execute()
--- End of stack trace from previous location where exception was thrown ---
   at System.Runtime.ExceptionServices.ExceptionDispatchInfo.Throw()
   at System.Runtime.CompilerServices.TaskAwaiter.HandleNonSuccessAndDebuggerNotification(Task task)
   at System.Runtime.CompilerServices.TaskAwaiter`1.GetResult()
   at Suftnet.Cos.Mobile.DeliveryOrderController.<Create>d__8.MoveNext() in E:\Git\Web\Irit\Irit\Suftnet.Cos\Controllers\Api\v1\DeliveryOrderController.cs:line 93
--- End of stack trace from previous location where exception was thrown ---
   at System.Runtime.ExceptionServices.ExceptionDispatchInfo.Throw()
   at System.Runtime.CompilerServices.TaskAwaiter.HandleNonSuccessAndDebuggerNotification(Task task)
   at System.Threading.Tasks.TaskHelpersExtensions.<CastToObject>d__3`1.MoveNext()
--- End of stack trace from previous location where exception was thrown ---
   at System.Runtime.ExceptionServices.ExceptionDispatchInfo.Throw()
   at System.Runtime.CompilerServices.TaskAwaiter.HandleNonSuccessAndDebuggerNotification(Task task)
   at System.Web.Http.Controllers.ApiControllerActionInvoker.<InvokeActionAsyncCore>d__0.MoveNext()
--- End of stack trace from previous location where exception was thrown ---
   at System.Runtime.ExceptionServices.ExceptionDispatchInfo.Throw()
   at System.Runtime.CompilerServices.TaskAwaiter.HandleNonSuccessAndDebuggerNotification(Task task)
   at System.Web.Http.Controllers.ActionFilterResult.<ExecuteAsync>d__2.MoveNext()
--- End of stack trace from previous location where exception was thrown ---
   at System.Runtime.ExceptionServices.ExceptionDispatchInfo.Throw()
   at System.Runtime.CompilerServices.TaskAwaiter.HandleNonSuccessAndDebuggerNotification(Task task)
   at System.Web.Http.Controllers.ExceptionFilterResult.<ExecuteAsync>d__0.MoveNext()Messages
An error occurred while updating the entries. See the inner exception for details.
--------------------------------------------
Request.Body = {"orderId":"6ad41dbf-ed84-4ee5-8274-ba1d94bef3f6","userId":"fee9a2ef-c152-45b6-a2ee-5c74fe1cabf9"}
--------------------------------------------
Inner Exception
Messages
An error occurred while updating the entries. See the inner exception for details.Messages
The conversion of a datetime2 data type to a smalldatetime data type resulted in an out-of-range value.
The statement has been terminated.
--------------------------------------------------------------------------------------------
20210312 17:51:10 [18] ERROR Web [(null)] - StackTrace
   at Suftnet.Cos.Web.Command.AcceptDeliveryOrderCommand.AcceptOrder() in E:\Git\Web\Irit\Irit\Suftnet.Cos\Command\AcceptOrderCommand.cs:line 42
   at Suftnet.Cos.Web.Command.AcceptDeliveryOrderCommand.Execute() in E:\Git\Web\Irit\Irit\Suftnet.Cos\Command\AcceptOrderCommand.cs:line 35
   at Suftnet.Cos.Mobile.DeliveryOrderController.<Create>b__9_0() in E:\Git\Web\Irit\Irit\Suftnet.Cos\Controllers\Api\v1\DeliveryOrderController.cs:line 99
   at System.Threading.Tasks.Task.Execute()
--- End of stack trace from previous location where exception was thrown ---
   at System.Runtime.ExceptionServices.ExceptionDispatchInfo.Throw()
   at System.Runtime.CompilerServices.TaskAwaiter.HandleNonSuccessAndDebuggerNotification(Task task)
   at System.Runtime.CompilerServices.TaskAwaiter.GetResult()
   at Suftnet.Cos.Mobile.DeliveryOrderController.<Create>d__9.MoveNext() in E:\Git\Web\Irit\Irit\Suftnet.Cos\Controllers\Api\v1\DeliveryOrderController.cs:line 99
--- End of stack trace from previous location where exception was thrown ---
   at System.Runtime.ExceptionServices.ExceptionDispatchInfo.Throw()
   at System.Runtime.CompilerServices.TaskAwaiter.HandleNonSuccessAndDebuggerNotification(Task task)
   at System.Threading.Tasks.TaskHelpersExtensions.<CastToObject>d__3`1.MoveNext()
--- End of stack trace from previous location where exception was thrown ---
   at System.Runtime.ExceptionServices.ExceptionDispatchInfo.Throw()
   at System.Runtime.CompilerServices.TaskAwaiter.HandleNonSuccessAndDebuggerNotification(Task task)
   at System.Web.Http.Controllers.ApiControllerActionInvoker.<InvokeActionAsyncCore>d__0.MoveNext()
--- End of stack trace from previous location where exception was thrown ---
   at System.Runtime.ExceptionServices.ExceptionDispatchInfo.Throw()
   at System.Runtime.CompilerServices.TaskAwaiter.HandleNonSuccessAndDebuggerNotification(Task task)
   at System.Web.Http.Controllers.ActionFilterResult.<ExecuteAsync>d__2.MoveNext()
--- End of stack trace from previous location where exception was thrown ---
   at System.Runtime.ExceptionServices.ExceptionDispatchInfo.Throw()
   at System.Runtime.CompilerServices.TaskAwaiter.HandleNonSuccessAndDebuggerNotification(Task task)
   at System.Runtime.CompilerServices.TaskAwaiter`1.GetResult()
   at Suftnet.Cos.Web.ActionFilter.AddChallengeOnUnauthorizedResult.<ExecuteAsync>d__7.MoveNext() in E:\Git\Web\Irit\Irit\Suftnet.Cos\Infrastructure\ActionFilter\AddChallengeOnUnauthorizedResult.cs:line 25
--- End of stack trace from previous location where exception was thrown ---
   at System.Runtime.ExceptionServices.ExceptionDispatchInfo.Throw()
   at System.Runtime.CompilerServices.TaskAwaiter.HandleNonSuccessAndDebuggerNotification(Task task)
   at System.Web.Http.Controllers.AuthenticationFilterResult.<ExecuteAsync>d__0.MoveNext()
--- End of stack trace from previous location where exception was thrown ---
   at System.Runtime.ExceptionServices.ExceptionDispatchInfo.Throw()
   at System.Runtime.CompilerServices.TaskAwaiter.HandleNonSuccessAndDebuggerNotification(Task task)
   at System.Web.Http.Controllers.ExceptionFilterResult.<ExecuteAsync>d__0.MoveNext()Messages
Object reference not set to an instance of an object.
--------------------------------------------
Request.Body = {"orderId":"0900b42b-3b3f-43b9-9d2d-6fa7a802488d"}

--------------------------------------------------------------------------------------------
20210313 10:37:56 [12] ERROR Web [(null)] - StackTrace
   at Suftnet.Cos.Web.Command.AcceptDeliveryOrderCommand.AcceptOrder() in E:\Git\Web\Irit\Irit\Suftnet.Cos\Command\AcceptOrderCommand.cs:line 34
   at Suftnet.Cos.Web.Command.AcceptDeliveryOrderCommand.Execute() in E:\Git\Web\Irit\Irit\Suftnet.Cos\Command\AcceptOrderCommand.cs:line 28
   at Suftnet.Cos.Mobile.DeliveryOrderController.<UpdateStatus>b__12_0() in E:\Git\Web\Irit\Irit\Suftnet.Cos\Controllers\Api\v1\DeliveryOrderController.cs:line 138
   at System.Threading.Tasks.Task.Execute()
--- End of stack trace from previous location where exception was thrown ---
   at System.Runtime.ExceptionServices.ExceptionDispatchInfo.Throw()
   at System.Runtime.CompilerServices.TaskAwaiter.HandleNonSuccessAndDebuggerNotification(Task task)
   at System.Runtime.CompilerServices.TaskAwaiter.GetResult()
   at Suftnet.Cos.Mobile.DeliveryOrderController.<UpdateStatus>d__12.MoveNext() in E:\Git\Web\Irit\Irit\Suftnet.Cos\Controllers\Api\v1\DeliveryOrderController.cs:line 138
--- End of stack trace from previous location where exception was thrown ---
   at System.Runtime.ExceptionServices.ExceptionDispatchInfo.Throw()
   at System.Runtime.CompilerServices.TaskAwaiter.HandleNonSuccessAndDebuggerNotification(Task task)
   at System.Threading.Tasks.TaskHelpersExtensions.<CastToObject>d__3`1.MoveNext()
--- End of stack trace from previous location where exception was thrown ---
   at System.Runtime.ExceptionServices.ExceptionDispatchInfo.Throw()
   at System.Runtime.CompilerServices.TaskAwaiter.HandleNonSuccessAndDebuggerNotification(Task task)
   at System.Web.Http.Controllers.ApiControllerActionInvoker.<InvokeActionAsyncCore>d__0.MoveNext()
--- End of stack trace from previous location where exception was thrown ---
   at System.Runtime.ExceptionServices.ExceptionDispatchInfo.Throw()
   at System.Runtime.CompilerServices.TaskAwaiter.HandleNonSuccessAndDebuggerNotification(Task task)
   at System.Web.Http.Controllers.ActionFilterResult.<ExecuteAsync>d__2.MoveNext()
--- End of stack trace from previous location where exception was thrown ---
   at System.Runtime.ExceptionServices.ExceptionDispatchInfo.Throw()
   at System.Runtime.CompilerServices.TaskAwaiter.HandleNonSuccessAndDebuggerNotification(Task task)
   at System.Runtime.CompilerServices.TaskAwaiter`1.GetResult()
   at Suftnet.Cos.Web.ActionFilter.AddChallengeOnUnauthorizedResult.<ExecuteAsync>d__7.MoveNext() in E:\Git\Web\Irit\Irit\Suftnet.Cos\Infrastructure\ActionFilter\AddChallengeOnUnauthorizedResult.cs:line 25
--- End of stack trace from previous location where exception was thrown ---
   at System.Runtime.ExceptionServices.ExceptionDispatchInfo.Throw()
   at System.Runtime.CompilerServices.TaskAwaiter.HandleNonSuccessAndDebuggerNotification(Task task)
   at System.Web.Http.Controllers.AuthenticationFilterResult.<ExecuteAsync>d__0.MoveNext()
--- End of stack trace from previous location where exception was thrown ---
   at System.Runtime.ExceptionServices.ExceptionDispatchInfo.Throw()
   at System.Runtime.CompilerServices.TaskAwaiter.HandleNonSuccessAndDebuggerNotification(Task task)
   at System.Web.Http.Controllers.ExceptionFilterResult.<ExecuteAsync>d__0.MoveNext()Messages
Object reference not set to an instance of an object.
--------------------------------------------
Request.Body = {"orderId":"d2a5959d-682e-4095-a282-9a6f17382fec","statusId":"1e6f1192-c4f3-428c-9762-152753b059b7"}

--------------------------------------------------------------------------------------------
